<?xml version="1.0"?>
<robot xmlns:xacro="http://ros.org/wiki/xacro">
<xacro:macro name="abb_irb1600id" params="prefix">
    <!-- link list -->
    <link name="${prefix}base_link">
        <visual>
            <origin xyz="0 0 0" rpy="0 0 0"/>
            <geometry>
                <mesh filename="package://abb_irb1600id_support/meshes/irb1600id/visual/base_link.stl"/>
            </geometry>
            <material name="abb_orange">
                <color rgba="1 0.43 0 1"/>
            </material>
        </visual>
        <collision>
            <geometry>
                <mesh filename="package://abb_irb1600id_support/meshes/irb1600id/collision/base_link.stl"/>
            </geometry>
            <material name="yellow">
                <color rgba="0 1 1 1"/>
            </material>
        </collision>
    </link>
    <link name="${prefix}link_1">
        <visual>
            <origin xyz="0 0 0" rpy="0 0 0"/>
            <geometry>
                <mesh filename="package://abb_irb1600id_support/meshes/irb1600id/visual/link_1.stl"/>
            </geometry>
            <material name="abb_orange"/>
        </visual>
        <collision>
            <origin xyz="0 0 0" rpy="0 0 0"/>
            <geometry>
                <mesh filename="package://abb_irb1600id_support/meshes/irb1600id/collision/link_1.stl"/>
            </geometry>
            <material name="yellow"/>
        </collision>
    </link>
    <link name="${prefix}link_2">
        <visual>
            <origin xyz="0 0 0" rpy="0 0 0"/>
            <geometry>
                <mesh filename="package://abb_irb1600id_support/meshes/irb1600id/visual/link_2.stl"/>
            </geometry>
            <material name="abb_orange"/>
        </visual>
        <collision>
            <origin xyz="0 0 0" rpy="0 0 0"/>
            <geometry>
                <mesh filename="package://abb_irb1600id_support/meshes/irb1600id/collision/link_2_whole.stl"/>
            </geometry>
            <material name="yellow"/>
        </collision>
    </link>
    <link name="${prefix}link_3">
        <visual>
            <origin xyz="0 0 0" rpy="0 0 0"/>
            <geometry>
                <mesh filename="package://abb_irb1600id_support/meshes/irb1600id/visual/link_3.stl"/>
            </geometry>
            <material name="abb_orange"/>
        </visual>
        <collision>
            <origin xyz="0 0 0" rpy="0 0 0"/>
            <geometry>
                <mesh filename="package://abb_irb1600id_support/meshes/irb1600id/collision/link_3.stl"/>
            </geometry>
            <material name="yellow"/>
        </collision>
    </link>
    <link name="${prefix}link_4">
        <visual>
            <origin xyz="0 0 0" rpy="0 0 0"/>
            <geometry>
                <mesh filename="package://abb_irb1600id_support/meshes/irb1600id/visual/link_4.stl"/>
            </geometry>
            <material name="abb_orange"/>
        </visual>
        <collision>
            <origin xyz="0 0 0" rpy="0 0 0"/>
            <geometry>
                <mesh filename="package://abb_irb1600id_support/meshes/irb1600id/collision/link_4.stl"/>
            </geometry>
            <material name="yellow"/>
        </collision>
    </link>
    <link name="${prefix}link_5">
        <visual>
            <origin xyz="0 0 0" rpy="0 0 0"/>
            <geometry>
                <mesh filename="package://abb_irb1600id_support/meshes/irb1600id/visual/link_5.stl"/>
            </geometry>
            <material name="abb_orange"/>
        </visual>
        <collision>
            <origin xyz="0 0 0" rpy="0 0 0"/>
            <geometry>
                <mesh filename="package://abb_irb1600id_support/meshes/irb1600id/collision/link_5.stl"/>
            </geometry>
            <material name="yellow"/>
        </collision>
    </link>
    <link name="${prefix}link_6">
        <visual>
            <origin xyz="0 0 0" rpy="0 0 0"/>
            <geometry>
                <mesh filename="package://abb_irb1600id_support/meshes/irb1600id/visual/link_6.stl"/>
            </geometry>
            <material name="abb_orange"/>
        </visual>
        <collision>
            <origin xyz="0 0 0" rpy="0 0 0"/>
            <geometry>
                <mesh filename="package://abb_irb1600id_support/meshes/irb1600id/collision/link_6.stl"/>
            </geometry>
            <material name="yellow"/>
        </collision>
    </link>
    <link name="${prefix}tool0"/>
    <!-- end of link list -->

    <!-- joint list -->
    <joint name="${prefix}joint_1" type="revolute">
        <origin xyz="0 0 0" rpy="0 0 0"/>
        <parent link="${prefix}base_link"/>
        <child link="${prefix}link_1"/>
        <axis xyz="0 0 1"/>
        <limit lower="-3.1416" upper="3.1416" effort="0" velocity="3.142"/>
        <calibration rising="0" falling="0"/>
        <dynamics damping="0" friction="0"/>
    </joint>
    <joint name="${prefix}joint_2" type="revolute">
        <origin xyz="0.15 0 0.4865" rpy="0 0 0"/>
        <parent link="${prefix}link_1"/>
        <child link="${prefix}link_2"/>
        <axis xyz="0 1 0"/>
        <limit lower="-1.5708" upper="2.618" effort="0" velocity="3.142"/>
        <calibration rising="0" falling="0"/>
        <dynamics damping="0" friction="0"/>
    </joint>
    <joint name="${prefix}joint_3" type="revolute">
        <origin xyz="0 0 0.700" rpy="0 0 0"/>
        <parent link="${prefix}link_2"/>
        <child link="${prefix}link_3"/>
        <axis xyz="0 1 0"/>
        <limit lower="-4.1539" upper="1.3789" effort="0" velocity="3.142"/>
        <calibration rising="0" falling="0"/>
        <dynamics damping="0" friction="0"/>
    </joint>
    <joint name="${prefix}joint_4" type="revolute">
        <origin xyz="0.151 0 0.11" rpy="0 0 0"/>
        <parent link="${prefix}link_3"/>
        <child link="${prefix}link_4"/>
        <axis xyz="1 0 0"/>
        <limit lower="-2.7925" upper="2.7925" effort="0" velocity="5.585"/>
        <calibration rising="0" falling="0"/>
        <dynamics damping="0" friction="0"/>
    </joint>
    <joint name="${prefix}joint_5" type="revolute">
        <origin xyz="0.489 0 0" rpy="0 0 0"/>
        <parent link="${prefix}link_4"/>
        <child link="${prefix}link_5"/>
        <axis xyz="0 1 0"/>
        <limit lower="-1.5708" upper="2.3562" effort="0" velocity="6.632"/>
        <calibration rising="0" falling="0"/>
        <dynamics damping="0" friction="0"/>
    </joint>
    <joint name="${prefix}joint_6" type="revolute">
        <origin xyz="0.2 0 0" rpy="0 0 0"/>
        <parent link="${prefix}link_5"/>
        <child link="${prefix}link_6"/>
        <axis xyz="1 0 0"/>
        <limit lower="-3.4907" upper="3.4907" effort="0" velocity="8.029"/>
        <calibration rising="0" falling="0"/>
        <dynamics damping="0" friction="0"/>
    </joint>
    <joint name="${prefix}joint_6-tool0" type="fixed">
        <parent link="${prefix}link_6"/>
        <child link="${prefix}tool0"/>
        <origin xyz="0 0 0" rpy="0 0 0"/>
    </joint>
    <!-- end of joint list -->
</xacro:macro>
</robot>
